Workbook

Sheet Curriculum
A1: Mechatronics & Robotics English Vocabulary — المنهج الكامل
A2: 7-stage learning path: Robotics Fundamentals → Control & Motion → Motors & Sensors → Embedded Systems → Industrial Automation → Robot Operation → Troubleshooting & Job Interviews
A4: Stage # | B4: Stage | C4: المرحلة | D4: What you learn | E4: ماذا ستتعلم | F4: Terms | G4: Beginner | H4: Intermediate | I4: Advanced | J4: Go to sheet
A5: 1 | B5: Robotics Fundamentals | C5: أساسيات الروبوتات | D5: What a robot is: parts, joints, robot types, basic geometry and terms. | E5: ما هو الروبوت: أجزاؤه ومفاصله وأنواعه والمصطلحات والهندسة الأساسية. | F5: =COUNTIF('All Terms'!$M$5:$M$436,A5) -> 100 | G5: =COUNTIFS('All Terms'!$M$5:$M$436,$A5,'All Terms'!$L$5:$L$436,"Beginner") -> 58 | H5: =COUNTIFS('All Terms'!$M$5:$M$436,$A5,'All Terms'!$L$5:$L$436,"Intermediate") -> 12 | I5: =COUNTIFS('All Terms'!$M$5:$M$436,$A5,'All Terms'!$L$5:$L$436,"Advanced") -> 30 | J5: S1 Fundamentals
A6: 2 | B6: Control & Motion | C6: التحكم والحركة | D6: Kinematics, feedback, PID, paths, trajectories, accuracy and the math behind them. | E6: الكينماتيكا والتغذية الراجعة وPID والمسارات والدقة والرياضيات المرتبطة بها. | F6: =COUNTIF('All Terms'!$M$5:$M$436,A6) -> 110 | G6: =COUNTIFS('All Terms'!$M$5:$M$436,$A6,'All Terms'!$L$5:$L$436,"Beginner") -> 16 | H6: =COUNTIFS('All Terms'!$M$5:$M$436,$A6,'All Terms'!$L$5:$L$436,"Intermediate") -> 39 | I6: =COUNTIFS('All Terms'!$M$5:$M$436,$A6,'All Terms'!$L$5:$L$436,"Advanced") -> 55 | J6: S2 Control & Motion
A7: 3 | B7: Motors & Sensors | C7: المحركات والحساسات | D7: Actuators, motors, drives, gears, encoders and all kinds of sensors. | E7: المشغّلات والمحركات والمخفضات والتروس والمُرمِّزات وأنواع الحساسات. | F7: =COUNTIF('All Terms'!$M$5:$M$436,A7) -> 76 | G7: =COUNTIFS('All Terms'!$M$5:$M$436,$A7,'All Terms'!$L$5:$L$436,"Beginner") -> 20 | H7: =COUNTIFS('All Terms'!$M$5:$M$436,$A7,'All Terms'!$L$5:$L$436,"Intermediate") -> 35 | I7: =COUNTIFS('All Terms'!$M$5:$M$436,$A7,'All Terms'!$L$5:$L$436,"Advanced") -> 21 | J7: S3 Motors & Sensors
A8: 4 | B8: Embedded Systems | C8: الأنظمة المضمنة | D8: Microcontrollers, firmware, interrupts, electronics, and controller hardware. | E8: المتحكمات الدقيقة والبرامج الثابتة والمقاطعات والإلكترونيات وعتاد المتحكم. | F8: =COUNTIF('All Terms'!$M$5:$M$436,A8) -> 29 | G8: =COUNTIFS('All Terms'!$M$5:$M$436,$A8,'All Terms'!$L$5:$L$436,"Beginner") -> 9 | H8: =COUNTIFS('All Terms'!$M$5:$M$436,$A8,'All Terms'!$L$5:$L$436,"Intermediate") -> 12 | I8: =COUNTIFS('All Terms'!$M$5:$M$436,$A8,'All Terms'!$L$5:$L$436,"Advanced") -> 8 | J8: S4 Embedded Systems
A9: 5 | B9: Industrial Automation | C9: الأتمتة الصناعية | D9: PLCs, work cells, integrators, tooling, and real factory applications. | E9: المتحكمات المنطقية وخلايا العمل والمُكامِلون والأدوات والتطبيقات المصنعية. | F9: =COUNTIF('All Terms'!$M$5:$M$436,A9) -> 52 | G9: =COUNTIFS('All Terms'!$M$5:$M$436,$A9,'All Terms'!$L$5:$L$436,"Beginner") -> 23 | H9: =COUNTIFS('All Terms'!$M$5:$M$436,$A9,'All Terms'!$L$5:$L$436,"Intermediate") -> 23 | I9: =COUNTIFS('All Terms'!$M$5:$M$436,$A9,'All Terms'!$L$5:$L$436,"Advanced") -> 6 | J9: S5 Industrial Automation
A10: 6 | B10: Robot Operation | C10: تشغيل الروبوتات | D10: Programming, teaching, operating modes, safety rules and specifications. | E10: البرمجة والتعليم وأنماط التشغيل وقواعد السلامة والمواصفات. | F10: =COUNTIF('All Terms'!$M$5:$M$436,A10) -> 49 | G10: =COUNTIFS('All Terms'!$M$5:$M$436,$A10,'All Terms'!$L$5:$L$436,"Beginner") -> 18 | H10: =COUNTIFS('All Terms'!$M$5:$M$436,$A10,'All Terms'!$L$5:$L$436,"Intermediate") -> 21 | I10: =COUNTIFS('All Terms'!$M$5:$M$436,$A10,'All Terms'!$L$5:$L$436,"Advanced") -> 10 | J10: S6 Robot Operation
A11: 7 | B11: Troubleshooting & Job Interviews | C11: استكشاف الأعطال والمقابلات المهنية | D11: Maintenance, downtime, faults, reliability, quality, and typical interview terms. | E11: الصيانة والتوقف والأعطال والموثوقية والجودة ومصطلحات المقابلات المعتادة. | F11: =COUNTIF('All Terms'!$M$5:$M$436,A11) -> 16 | G11: =COUNTIFS('All Terms'!$M$5:$M$436,$A11,'All Terms'!$L$5:$L$436,"Beginner") -> 7 | H11: =COUNTIFS('All Terms'!$M$5:$M$436,$A11,'All Terms'!$L$5:$L$436,"Intermediate") -> 5 | I11: =COUNTIFS('All Terms'!$M$5:$M$436,$A11,'All Terms'!$L$5:$L$436,"Advanced") -> 4 | J11: S7 Troubleshoot & Interview
B12: Total | C12: المجموع | F12: =SUM(F5:F11) -> 432 | G12: =SUM(G5:G11) -> 151 | H12: =SUM(H5:H11) -> 147 | I12: =SUM(I5:I11) -> 134
B14: Column guide / شرح الأعمدة
B15: content_id | D15: Permanent ID, e.g. S3-SENS-014 = stage 3, category SENS, item 14. Never renumber it.
B16: Term / Arabic meaning | D16: The English term and its Arabic meaning
B17: Pronunciation | D17: Simple English respelling; capital letters = stressed syllable
B18: Category | D18: Topic of the term (Kinematics, Sensors, Safety...)
B19: Simple English definition | D19: Short, plain-English explanation
B20: Example 1 / 2 | D20: Two example sentences, each with an Arabic translation
B21: Difficulty level | D21: Beginner / Intermediate / Advanced
B22: Interview priority | D22: High = used in the Interview Q&A or Troubleshooting Guide, or key career vocabulary
B23: Linked Q&A / troubleshooting | D23: IDs of interview questions and fault cases that use this term
B24: Source / source_url | D24: Which of the 3 sources the term came from, and the link
B25: Copyright/source note | D25: What was taken from the source and what is original

Sheet All Terms
A1: All Terms — جميع المصطلحات (sorted by curriculum stage, then level)
A2: 432 unique terms merged from 3 sources. Use the filter arrows on row 4 to filter by stage, level, category, priority or source.
A4: content_id | B4: # | C4: Term | D4: Arabic meaning | E4: Pronunciation | F4: Category | G4: Simple English definition | H4: Example 1 | I4: Arabic translation 1 | J4: Example 2 | K4: Arabic translation 2 | L4: Difficulty level | M4: Stage # | N4: Curriculum stage | O4: Interview priority | P4: Linked Q&A / troubleshooting | Q4: Source | R4: source_url | S4: Copyright/source note
A5: S1-KINE-001 | B5: 1 | C5: Acceleration | D5: التسارع | E5: ak-sel-er-AY-shun | F5: Kinematics | G5: A change in how fast something moves or in its direction of travel. | H5: The robot needs high acceleration to move quickly. | I5: يحتاج الروبوت إلى تسارع عالٍ ليتحرك بسرعة. | J5: Acceleration is the change of velocity over time. | K5: التسارع هو تغير السرعة عبر الزمن. | L5: Beginner | M5: 1 | N5: 1 – Robotics Fundamentals | أساسيات الروبوتات | O5: Normal | Q5: FutureLearn (Univ. of Reading) | R5: https://ugc.futurelearn.com/uploads/files/7a/0f/7a0fcf86-09f0-4ebf-a134-02b1290a950e/Glossary.pdf | S5: Definition paraphrased from the listed source(s); pronunciation, Arabic, examples and level are original additions.
A6: S1-PROG-001 | B6: 2 | C6: Algorithm | D6: خوارزمية | E6: AL-guh-rith-um | F6: Programming | G6: A set of steps for solving a problem. | H6: The algorithm tells the robot how to find the shortest path. | I6: تخبر الخوارزمية الروبوت كيف يجد أقصر مسار. | J6: We improved the algorithm to reduce the calculation time. | K6: حسّنا الخوارزمية لتقليل زمن الحساب. | L6: Beginner | M6: 1 | N6: 1 – Robotics Fundamentals | أساسيات الروبوتات | O6: Normal | Q6: FutureLearn (Univ. of Reading) + Productivity Inc | R6: https://ugc.futurelearn.com/uploads/files/7a/0f/7a0fcf86-09f0-4ebf-a134-02b1290a950e/Glossary.pdf | https://www.productivity.com/wp-content/uploads/2015/04/PI_RoboticGlossaryTerms.pdf | S6: Definition paraphrased from the listed source(s); pronunciation, Arabic, examples and level are original additions.
A7: S1-ROBT-001 | B7: 3 | C7: Android | D7: روبوت شبيه بالإنسان (أندرويد) | E7: AN-droyd | F7: Robot Types | G7: A robot that resembles a human to some degree. | H7: An android is a robot that looks like a human. | I7: الأندرويد روبوت يشبه الإنسان. | J7: The museum has an android that greets visitors. | K7: لدى المتحف روبوت شبيه بالإنسان يستقبل الزوار. | L7: Beginner | M7: 1 | N7: 1 – Robotics Fundamentals | أساسيات الروبوتات | O7: Normal | Q7: FutureLearn (Univ. of Reading) | R7: https://ugc.futurelearn.com/uploads/files/7a/0f/7a0fcf86-09f0-4ebf-a134-02b1290a950e/Glossary.pdf | S7: Definition paraphrased from the listed source(s); pronunciation, Arabic, examples and level are original additions.
A8: S1-MECH-001 | B8: 4 | C8: Arm | D8: الذراع | E8: ARM | F8: Mechanical | G8: The linked, powered segments of a manipulator that move the wrist and end-effector, excluding the end-effector itself. | H8: The robot arm can lift up to ten kilograms. | I8: يستطيع ذراع الروبوت رفع ما يصل إلى عشرة كيلوغرامات. | J8: The arm has six joints and a gripper at its end. | K8: للذراع ستة مفاصل وقابض في نهايتها. | L8: Beginner | M8: 1 | N8: 1 – Robotics Fundamentals | أساسيات الروبوتات | O8: Normal | Q8: Productivity Inc | R8: https://www.productivity.com/wp-content/uploads/2015/04/PI_RoboticGlossaryTerms.pdf | S8: Definition paraphrased from the listed source(s); pronunciation, Arabic, examples and level are original additions.
A9: S1-CMAI-001 | B9: 5 | C9: Artificial Intelligence | D9: الذكاء الاصطناعي | E9: ar-tih-FISH-ul in-TEL-ih-juns | F9: Computing & AI | G9: Intelligence shown by a machine. | H9: Artificial intelligence lets machines learn from data. | I9: يتيح الذكاء الاصطناعي للآلات التعلم من البيانات. | J9: Modern robots use artificial intelligence to recognize objects. | K9: تستخدم الروبوتات الحديثة الذكاء الاصطناعي للتعرف على الأجسام. | L9: Beginner | M9: 1 | N9: 1 – Robotics Fundamentals | أساسيات الروبوتات | O9: Normal | Q9: FutureLearn (Univ. of Reading) | R9: https://ugc.futurelearn.com/uploads/files/7a/0f/7a0fcf86-09f0-4ebf-a134-02b1290a950e/Glossary.pdf | S9: Definition paraphrased from the listed source(s); pronunciation, Arabic, examples and level are original additions.
A10: S1-ROBT-003 | B10: 6 | C10: Autonomous | D10: ذاتي التشغيل / مستقل | E10: aw-TON-uh-mus | F10: Robot Types | G10: Procedures that run without worker involvement and follow pre-programmed operations. | H10: An autonomous robot makes its own decisions without a human. | I10: يتخذ الروبوت الذاتي التشغيل قراراته بنفسه دون إنسان. | J10: Autonomous vehicles use sensors to avoid obstacles. | K10: تستخدم المركبات ذاتية القيادة الحساسات لتجنب العوائق. | L10: Beginner | M10: 1 | N10: 1 – Robotics Fundamentals | أساسيات الروبوتات | O10: Normal | Q10: FutureLearn (Univ. of Reading) + Productivity Inc | R10: https://ugc.futurelearn.com/uploads/files/7a/0f/7a0fcf86-09f0-4ebf-a134-02b1290a950e/Glossary.pdf | https://www.productivity.com/wp-content/uploads/2015/04/PI_RoboticGlossaryTerms.pdf | S10: Definition paraphrased from the listed source(s); pronunciation, Arabic, examples and level are original additions.
A11: S1-KINE-002 | B11: 7 | C11: Axis | D11: محور | E11: AK-sis | F11: Kinematics | G11: A direction or line of rotation along which a robot moves; most industrial robots have four or six. | H11: This robot has six axes of movement. | I11: لهذا الروبوت ستة محاور للحركة. | J11: Each axis is driven by its own servo motor. | K11: يُدار كل محور بمحرك مؤازر خاص به. | L11: Beginner | M11: 1 | N11: 1 – Robotics Fundamentals | أساسيات الروبوتات | O11: High | P11: S7-INTV-002 | Q11: Productivity Inc | R11: https://www.productivity.com/wp-content/uploads/2015/04/PI_RoboticGlossaryTerms.pdf | S11: Definition paraphrased from the listed source(s); pronunciation, Arabic, examples and level are original additions.
A12: S1-MECH-003 | B12: 8 | C12: Base | D12: القاعدة | E12: BAYSS | F12: Mechanical | G12: The stable platform to which a robotic arm is attached. | H12: The robot arm is bolted to a stable base. | I12: الذراع الآلية مثبّتة بمسامير على قاعدة ثابتة. | J12: The base must be level before installation. | K12: يجب أن تكون القاعدة مستوية قبل التركيب. | L12: Beginner | M12: 1 | N12: 1 – Robotics Fundamentals | أساسيات الروبوتات | O12: Normal | Q12: Productivity Inc | R12: https://www.productivity.com/wp-content/uploads/2015/04/PI_RoboticGlossaryTerms.pdf | S12: Definition paraphrased from the listed source(s); pronunciation, Arabic, examples and level are original additions.
A13: S1-SWDS-001 | B13: 9 | C13: CAD (Computer-Aided Design) | D13: التصميم بمساعدة الحاسوب | E13: KAD | F13: Software & Design | G13: Software for designing manufacturable parts, creating schematics, and simulating stresses on them. | H13: We drew the gripper in CAD before building it. | I13: رسمنا القابض في برنامج التصميم بمساعدة الحاسوب قبل تصنيعه. | J13: CAD software can simulate stress on a part. | K13: يستطيع برنامج التصميم بمساعدة الحاسوب محاكاة الإجهاد على القطعة. | L13: Beginner | M13: 1 | N13: 1 – Robotics Fundamentals | أساسيات الروبوتات | O13: Normal | Q13: Productivity Inc | R13: https://www.productivity.com/wp-content/uploads/2015/04/PI_RoboticGlossaryTerms.pdf | S13: Definition paraphrased from the listed source(s); pronunciation, Arabic, examples and level are original additions.
A14: S1-ROBT-006 | B14: 10 | C14: Cartesian Robot | D14: روبوت ديكارتي | E14: kar-TEE-zhun ROH-bot | F14: Robot Types | G14: A robot whose three linear joints run in the directions of a Cartesian coordinate system. | H14: A Cartesian robot has three linear axes. | I14: للروبوت الديكارتي ثلاثة محاور خطية. | J14: We used a Cartesian robot to stack boxes. | K14: استخدمنا روبوتاً ديكارتياً لتكديس الصناديق. | L14: Beginner | M14: 1 | N14: 1 – Robotics Fundamentals | أساسيات الروبوتات | O14: Normal | Q14: Productivity Inc | R14: https://www.productivity.com/wp-content/uploads/2015/04/PI_RoboticGlossaryTerms.pdf | S14: Definition paraphrased from the listed source(s); pronunciation, Arabic, examples and level are original additions.
A15: S1-MECH-004 | B15: 11 | C15: Chassis | D15: الهيكل | E15: SHAS-ee | F15: Mechanical | G15: The framework and internal parts of a machine, excluding its body or casing. | H15: The motors and batteries are mounted on the chassis. | I15: المحركات والبطاريات مركّبة على الهيكل. | J15: A strong chassis protects the electronics. | K15: الهيكل المتين يحمي الإلكترونيات. | L15: Beginner | M15: 1 | N15: 1 – Robotics Fundamentals | أساسيات الروبوتات | O15: Normal | Q15: Productivity Inc | R15: https://www.productivity.com/wp-content/uploads/2015/04/PI_RoboticGlossaryTerms.pdf | S15: Definition paraphrased from the listed source(s); pronunciation, Arabic, examples and level are original additions.
A16: S1-KINE-003 | B16: 12 | C16: Coordinates | D16: الإحداثيات | E16: koh-OR-dih-nits | F16: Kinematics | G16: A set of numbers that describes a position in two or three dimensions. | H16: The coordinates give the position of the point. | I16: تعطي الإحداثيات موضع النقطة. | J16: Enter the coordinates in millimeters. | K16: أدخل الإحداثيات بالملّيمترات. | L16: Beginner | M16: 1 | N16: 1 – Robotics Fundamentals | أساسيات الروبوتات | O16: Normal | Q16: FutureLearn (Univ. of Reading) | R16: https://ugc.futurelearn.com/uploads/files/7a/0f/7a0fcf86-09f0-4ebf-a134-02b1290a950e/Glossary.pdf | S16: Definition paraphrased from the listed source(s); pronunciation, Arabic, examples and level are original additions.
A17: S1-ROBT-009 | B17: 13 | C17: Cyborg | D17: سايبورغ (كائن سيبراني) | E17: SY-borg | F17: Robot Types | G17: An organism combining biological and mechanical or electronic parts. | H17: A cyborg combines a living body with machine parts. | I17: يجمع السايبورغ بين جسم حي وأجزاء آلية. | J17: Science fiction often shows cyborgs with robotic arms. | K17: يعرض الخيال العلمي غالباً سايبورغ بأذرع آلية. | L17: Beginner | M17: 1 | N17: 1 – Robotics Fundamentals | أساسيات الروبوتات | O17: Normal | Q17: FutureLearn (Univ. of Reading) | R17: https://ugc.futurelearn.com/uploads/files/7a/0f/7a0fcf86-09f0-4ebf-a134-02b1290a950e/Glossary.pdf | S17: Definition paraphrased from the listed source(s); pronunciation, Arabic, examples and level are original additions.
A18: S1-FUND-001 | B18: 14 | C18: Degrees | D18: الدرجات | E18: dih-GREEZ | F18: Fundamentals | G18: A unit for measuring angles, where a full turn is 360 degrees. | H18: A full circle has 360 degrees. | I18: للدائرة الكاملة 360 درجة. | J18: The joint rotates 90 degrees. | K18: يدور المفصل 90 درجة. | L18: Beginner | M18: 1 | N18: 1 – Robotics Fundamentals | أساسيات الروبوتات | O18: Normal | Q18: FutureLearn (Univ. of Reading) | R18: https://ugc.futurelearn.com/uploads/files/7a/0f/7a0fcf86-09f0-4ebf-a134-02b1290a950e/Glossary.pdf | S18: Definition paraphrased from the listed source(s); pronunciation, Arabic, examples and level are original additions.
A19: S1-KINE-004 | B19: 15 | C19: Degrees of Freedom (DOF) | D19: درجات الحرية | E19: dih-GREEZ uv FREE-dum | F19: Kinematics | G19: The number of independent parameters needed to define a system's position and orientation. | H19: This robot has six degrees of freedom. | I19: لهذا الروبوت ست درجات حرية. | J19: More degrees of freedom give more flexibility but harder control. | K19: مزيد من درجات الحرية يعطي مرونة أكبر لكن تحكماً أصعب. | L19: Beginner | M19: 1 | N19: 1 – Robotics Fundamentals | أساسيات الروبوتات | O19: High | P19: S7-INTV-002 | Q19: Engineers Universe + FutureLearn (Univ. of Reading) + Productivity Inc | R19: https://engineersuniverse.com/studios/mechatronics/mechatronics-terminology-glossary | https://ugc.futurelearn.com/uploads/files/7a/0f/7a0fcf86-09f0-4ebf-a134-02b1290a950e/Glossary.pdf | https://www.productivity.com/wp-content/uploads/2015/04/PI_RoboticGlossaryTerms.pdf | S19: Definition paraphrased from the listed source(s); pronunciation, Arabic, examples and level are original additions.
A20: S1-FUND-002 | B20: 16 | C20: Device | D20: جهاز | E20: dih-VYSE | F20: Fundamentals | G20: Hardware used to control parts of a system. | H20: Each device on the network has its own address. | I20: لكل جهاز على الشبكة عنوانه الخاص. | J20: The device controls part of the system. | K20: يتحكم الجهاز في جزء من النظام. | L20: Beginner | M20: 1 | N20: 1 – Robotics Fundamentals | أساسيات الروبوتات | O20: Normal | Q20: Productivity Inc | R20: https://www.productivity.com/wp-content/uploads/2015/04/PI_RoboticGlossaryTerms.pdf | S20: Definition paraphrased from the listed source(s); pronunciation, Arabic, examples and level are original additions.
A21: S1-ELEC-001 | B21: 17 | C21: Electronics | D21: الإلكترونيات | E21: ih-lek-TRON-iks | F21: Electronics | G21: The study of how electrons flow through and are controlled by components like batteries, resistors, and motors. | H21: Electronics is the study of circuits and components. | I21: الإلكترونيات هي دراسة الدوائر والمكونات. | J21: Robots depend on electronics to sense and control. | K21: تعتمد الروبوتات على الإلكترونيات للاستشعار والتحكم. | L21: Beginner | M21: 1 | N21: 1 – Robotics Fundamentals | أساسيات الروبوتات | O21: Normal | Q21: FutureLearn (Univ. of Reading) | R21: https://ugc.futurelearn.com/uploads/files/7a/0f/7a0fcf86-09f0-4ebf-a134-02b1290a950e/Glossary.pdf | S21: Definition paraphrased from the listed source(s); pronunciation, Arabic, examples and level are original additions.
A22: S1-TOOL-001 | B22: 18 | C22: End Effector | D22: المؤثر النهائي | E22: END ih-FEK-ter | F22: Tooling | G22: The tool at the end of a robot arm that interacts with the environment, such as a gripper or torch. | H22: The end effector of this robot is a vacuum gripper. | I22: المؤثر النهائي لهذا الروبوت قابض تفريغ. | J22: We changed the end effector to handle a larger part. | K22: غيّرنا المؤثر النهائي للتعامل مع قطعة أكبر. | L22: Beginner | M22: 1 | N22: 1 – Robotics Fundamentals | أساسيات الروبوتات | O22: Normal | Q22: Engineers Universe + FutureLearn (Univ. of Reading) + Productivity Inc | R22: https://engineersuniverse.com/studios/mechatronics/mechatronics-terminology-glossary | https://ugc.futurelearn.com/uploads/files/7a/0f/7a0fcf86-09f0-4ebf-a134-02b1290a950e/Glossary.pdf | https://www.productivity.com/wp-content/uploads/2015/04/PI_RoboticGlossaryTerms.pdf | S22: Definition paraphrased from the listed source(s); pronunciation, Arabic, examples and level are original additions.
A23: S1-FUND-003 | B23: 19 | C23: Energy Source | D23: مصدر الطاقة | E23: EN-er-jee SORS | F23: Fundamentals | G23: Where energy comes from, such as chemical, thermal, or mechanical processes. | H23: A battery is the energy source of a mobile robot. | I23: البطارية هي مصدر الطاقة للروبوت المتنقل. | J23: Choose an energy source that matches the actuators. | K23: اختر مصدر طاقة يناسب المشغّلات. | L23: Beginner | M23: 1 | N23: 1 – Robotics Fundamentals | أساسيات الروبوتات | O23: Normal | Q23: Productivity Inc | R23: https://www.productivity.com/wp-content/uploads/2015/04/PI_RoboticGlossaryTerms.pdf | S23: Definition paraphrased from the listed source(s); pronunciation, Arabic, examples and level are original additions.
A24: S1-FUND-004 | B24: 20 | C24: Flexibility | D24: المرونة | E24: flek-suh-BIL-ih-tee | F24: Fundamentals | G24: The range of diverse jobs a robot can perform. | H24: Flexibility lets one robot do many different jobs. | I24: تتيح المرونة لروبوت واحد القيام بمهام كثيرة مختلفة. | J24: The line needs flexibility because products change often. | K24: يحتاج الخط إلى المرونة لأن المنتجات تتغير كثيراً. | L24: Beginner | M24: 1 | N24: 1 – Robotics Fundamentals | أساسيات الروبوتات | O24: Normal | Q24: Productivity Inc | R24: https://www.productivity.com/wp-content/uploads/2015/04/PI_RoboticGlossaryTerms.pdf | S24: Definition paraphrased from the listed source(s); pronunciation, Arabic, examples and level are original additions.
A25: S1-DYNM-001 | B25: 21 | C25: Force | D25: القوة | E25: FORS | F25: Dynamics | G25: The strength behind an action or movement. | H25: The motor creates a force that moves the arm. | I25: يخلق المحرك قوة تحرك الذراع. | J25: Force is measured in newtons. | K25: تُقاس القوة بالنيوتن. | L25: Beginner | M25: 1 | N25: 1 – Robotics Fundamentals | أساسيات الروبوتات | O25: Normal | Q25: FutureLearn (Univ. of Reading) | R25: https://ugc.futurelearn.com/uploads/files/7a/0f/7a0fcf86-09f0-4ebf-a134-02b1290a950e/Glossary.pdf | S25: Definition paraphrased from the listed source(s); pronunciation, Arabic, examples and level are original additions.
A26: S1-TOOL-002 | B26: 22 | C26: Gripper | D26: القابض | E26: GRIP-er | F26: Tooling | G26: An end-effector that seizes and holds objects through pressure, magnetism, or vacuum. | H26: The gripper holds the bottle without dropping it. | I26: يمسك القابض الزجاجة دون إسقاطها. | J26: A magnetic gripper can pick up steel parts. | K26: يستطيع القابض المغناطيسي التقاط القطع الفولاذية. | L26: Beginner | M26: 1 | N26: 1 – Robotics Fundamentals | أساسيات الروبوتات | O26: High | P26: S7-TRBL-006 | Q26: FutureLearn (Univ. of Reading) + Productivity Inc | R26: https://ugc.futurelearn.com/uploads/files/7a/0f/7a0fcf86-09f0-4ebf-a134-02b1290a950e/Glossary.pdf | https://www.productivity.com/wp-content/uploads/2015/04/PI_RoboticGlossaryTerms.pdf | S26: Definition paraphrased from the listed source(s); pronunciation, Arabic, examples and level are original additions.
A27: S1-TOOL-003 | B27: 23 | C27: Hand | D27: اليد | E27: HAND | F27: Tooling | G27: A clamp or gripper used as an end-effector to grasp objects. | H27: The robot hand can hold small objects. | I27: تستطيع يد الروبوت حمل الأشياء الصغيرة. | J27: A two-finger hand is enough for this task. | K27: يد بإصبعين تكفي لهذه المهمة. | L27: Beginner | M27: 1 | N27: 1 – Robotics Fundamentals | أساسيات الروبوتات | O27: Normal | Q27: Productivity Inc | R27: https://www.productivity.com/wp-content/uploads/2015/04/PI_RoboticGlossaryTerms.pdf | S27: Definition paraphrased from the listed source(s); pronunciation, Arabic, examples and level are original additions.
A28: S1-EMBD-001 | B28: 24 | C28: Hardware | D28: العتاد (الأجهزة) | E28: HARD-wair | F28: Embedded Systems | G28: The physical parts of a computer. | H28: The hardware includes the motors, sensors, and controller. | I28: يشمل العتاد المحركات والحساسات والمتحكم. | J28: We replaced the faulty hardware, not the software. | K28: استبدلنا العتاد المعطوب وليس البرمجيات. | L28: Beginner | M28: 1 | N28: 1 – Robotics Fundamentals | أساسيات الروبوتات | O28: Normal | Q28: FutureLearn (Univ. of Reading) | R28: https://ugc.futurelearn.com/uploads/files/7a/0f/7a0fcf86-09f0-4ebf-a134-02b1290a950e/Glossary.pdf | S28: Definition paraphrased from the listed source(s); pronunciation, Arabic, examples and level are original additions.
A29: S1-ROBT-014 | B29: 25 | C29: Industrial Robot | D29: روبوت صناعي | E29: in-DUS-tree-ul ROH-bot | F29: Robot Types | G29: A reprogrammable multifunction manipulator that moves materials, parts, tools, or devices through varied programmed motions. | H29: An industrial robot is a reprogrammable multi-purpose manipulator. | I29: الروبوت الصناعي ذراع متعددة الأغراض قابلة لإعادة البرمجة. | J29: The industrial robot paints car bodies all day. | K29: يطلي الروبوت الصناعي هياكل السيارات طوال اليوم. | L29: Beginner | M29: 1 | N29: 1 – Robotics Fundamentals | أساسيات الروبوتات | O29: Normal | Q29: FutureLearn (Univ. of Reading) + Productivity Inc | R29: https://ugc.futurelearn.com/uploads/files/7a/0f/7a0fcf86-09f0-4ebf-a134-02b1290a950e/Glossary.pdf | https://www.productivity.com/wp-content/uploads/2015/04/PI_RoboticGlossaryTerms.pdf | S29: Definition paraphrased from the listed source(s); pronunciation, Arabic, examples and level are original additions.
A30: S1-ROBT-015 | B30: 26 | C30: Insect robot | D30: روبوت حشري | E30: IN-sekt ROH-bot | F30: Robot Types | G30: A small mobile robot. | H30: An insect robot is small and walks on six legs. | I30: الروبوت الحشري صغير ويمشي على ست أرجل. | J30: The insect robot can climb over small obstacles. | K30: يستطيع الروبوت الحشري تسلق عوائق صغيرة. | L30: Beginner | M30: 1 | N30: 1 – Robotics Fundamentals | أساسيات الروبوتات | O30: Normal | Q30: FutureLearn (Univ. of Reading) | R30: https://ugc.futurelearn.com/uploads/files/7a/0f/7a0fcf86-09f0-4ebf-a134-02b1290a950e/Glossary.pdf | S30: Definition paraphrased from the listed source(s); pronunciation, Arabic, examples and level are original additions.
A31: S1-CMAI-004 | B31: 27 | C31: Intelligence | D31: الذكاء | E31: in-TEL-ih-juns | F31: Computing & AI | G31: The capacity to gain and use skills and knowledge. | H31: Intelligence is the ability to learn and use knowledge. | I31: الذكاء هو القدرة على التعلم واستخدام المعرفة. | J31: Robots with some intelligence can adapt to change. | K31: الروبوتات ذات الذكاء المحدود تستطيع التكيف مع التغيير. | L31: Beginner | M31: 1 | N31: 1 – Robotics Fundamentals | أساسيات الروبوتات | O31: Normal | Q31: FutureLearn (Univ. of Reading) | R31: https://ugc.futurelearn.com/uploads/files/7a/0f/7a0fcf86-09f0-4ebf-a134-02b1290a950e/Glossary.pdf | S31: Definition paraphrased from the listed source(s); pronunciation, Arabic, examples and level are original additions.
A32: S1-ROBT-016 | B32: 28 | C32: Intelligent Robot | D32: روبوت ذكي | E32: in-TEL-ih-junt ROH-bot | F32: Robot Types | G32: A robot that can make performance choices based on sensory input with little human help. | H32: An intelligent robot can choose actions based on its sensors. | I32: يستطيع الروبوت الذكي اختيار الأفعال بناءً على حساساته. | J32: Intelligent robots need little help from humans. | K32: لا تحتاج الروبوتات الذكية إلا إلى مساعدة قليلة من البشر. | L32: Beginner | M32: 1 | N32: 1 – Robotics Fundamentals | أساسيات الروبوتات | O32: Normal | Q32: FutureLearn (Univ. of Reading) + Productivity Inc | R32: https://ugc.futurelearn.com/uploads/files/7a/0f/7a0fcf86-09f0-4ebf-a134-02b1290a950e/Glossary.pdf | https://www.productivity.com/wp-content/uploads/2015/04/PI_RoboticGlossaryTerms.pdf | S32: Definition paraphrased from the listed source(s); pronunciation, Arabic, examples and level are original additions.
A33: S1-MECH-005 | B33: 29 | C33: Joint | D33: مفصل | E33: JOYNT | F33: Mechanical | G33: A rotational or translational degree of freedom between links or between a link and the end-effector. | H33: Each joint of the robot has its own motor. | I33: لكل مفصل في الروبوت محركه الخاص. | J33: The elbow joint rotates up to 150 degrees. | K33: يدور مفصل المرفق حتى 150 درجة. | L33: Beginner | M33: 1 | N33: 1 – Robotics Fundamentals | أساسيات الروبوتات | O33: High | P33: S7-INTV-002 | Q33: FutureLearn (Univ. of Reading) + Productivity Inc | R33: https://ugc.futurelearn.com/uploads/files/7a/0f/7a0fcf86-09f0-4ebf-a134-02b1290a950e/Glossary.pdf | https://www.productivity.com/wp-content/uploads/2015/04/PI_RoboticGlossaryTerms.pdf | S33: Definition paraphrased from the listed source(s); pronunciation, Arabic, examples and level are original additions.
A34: S1-ROBT-017 | B34: 30 | C34: Jointed Arm Robot | D34: روبوت ذو ذراع مفصلية | E34: JOYN-tid ARM ROH-bot | F34: Robot Types | G34: A robot arm with two junctions that allow motion similar to a human shoulder and elbow. | H34: A jointed arm robot moves like a human shoulder and elbow. | I34: يتحرك الروبوت ذو الذراع المفصلية مثل كتف الإنسان ومرفقه. | J34: Most welding robots are jointed arm robots. | K34: معظم روبوتات اللحام ذات أذرع مفصلية. | L34: Beginner | M34: 1 | N34: 1 – Robotics Fundamentals | أساسيات الروبوتات | O34: Normal | Q34: Productivity Inc | R34: https://www.productivity.com/wp-content/uploads/2015/04/PI_RoboticGlossaryTerms.pdf | S34: Definition paraphrased from the listed source(s); pronunciation, Arabic, examples and level are original additions.
A35: S1-ETHC-001 | B35: 31 | C35: Law of Robotics | D35: قوانين الروبوتات | E35: LAW uv roh-BOT-iks | F35: Robotics Ethics | G35: Rules created by Isaac Asimov in his robot stories to govern robot behavior. | H35: Asimov wrote the three laws of robotics. | I35: كتب أسيموف قوانين الروبوتات الثلاثة. | J35: The first law says a robot must not harm a human. | K35: ينص القانون الأول على أن الروبوت يجب ألا يؤذي إنساناً. | L35: Beginner | M35: 1 | N35: 1 – Robotics Fundamentals | أساسيات الروبوتات | O35: Normal | Q35: FutureLearn (Univ. of Reading) | R35: https://ugc.futurelearn.com/uploads/files/7a/0f/7a0fcf86-09f0-4ebf-a134-02b1290a950e/Glossary.pdf | S35: Definition paraphrased from the listed source(s); pronunciation, Arabic, examples and level are original additions.
A36: S1-BIOL-014 | B36: 32 | C36: Light seeker | D36: باحث الضوء | E36: LYTE SEEK-er | F36: Biology-Inspired | G36: A Braitenberg vehicle that turns toward lights. | H36: A light seeker turns toward the light. | I36: يتجه باحث الضوء نحو الضوء. | J36: The light seeker robot found the lamp. | K36: وجد روبوت باحث الضوء المصباح. | L36: Beginner | M36: 1 | N36: 1 – Robotics Fundamentals | أساسيات الروبوتات | O36: Normal | Q36: FutureLearn (Univ. of Reading) | R36: https://ugc.futurelearn.com/uploads/files/7a/0f/7a0fcf86-09f0-4ebf-a134-02b1290a950e/Glossary.pdf | S36: Definition paraphrased from the listed source(s); pronunciation, Arabic, examples and level are original additions.
A37: S1-KINE-005 | B37: 33 | C37: Linear motion | D37: الحركة الخطية | E37: LIN-ee-er MOH-shun | F37: Kinematics | G37: Movement in a straight line rather than rotation. | H37: Linear motion is movement in a straight line. | I37: الحركة الخطية هي حركة في خط مستقيم. | J37: A linear actuator creates linear motion. | K37: ينتج المشغّل الخطي حركة خطية. | L37: Beginner | M37: 1 | N37: 1 – Robotics Fundamentals | أساسيات الروبوتات | O37: Normal | Q37: FutureLearn (Univ. of Reading) | R37: https://ugc.futurelearn.com/uploads/files/7a/0f/7a0fcf86-09f0-4ebf-a134-02b1290a950e/Glossary.pdf | S37: Definition paraphrased from the listed source(s); pronunciation, Arabic, examples and level are original additions.
A38: S1-MECH-006 | B38: 34 | C38: Link | D38: وصلة | E38: LINK | F38: Mechanical | G38: A rigid part of a manipulator that connects adjacent joints. | H38: A link is a rigid part between two joints. | I38: الوصلة جزء صلب بين مفصلين. | J38: The upper arm link is made of aluminum. | K38: وصلة الذراع العلوية مصنوعة من الألمنيوم. | L38: Beginner | M38: 1 | N38: 1 – Robotics Fundamentals | أساسيات الروبوتات | O38: Normal | Q38: FutureLearn (Univ. of Reading) + Productivity Inc | R38: https://ugc.futurelearn.com/uploads/files/7a/0f/7a0fcf86-09f0-4ebf-a134-02b1290a950e/Glossary.pdf | https://www.productivity.com/wp-content/uploads/2015/04/PI_RoboticGlossaryTerms.pdf | S38: Definition paraphrased from the listed source(s); pronunciation, Arabic, examples and level are original additions.
A39: S1-ROBT-018 | B39: 35 | C39: Manipulator | D39: المُناوِل (الذراع الآلية) | E39: muh-NIP-yuh-lay-ter | F39: Robot Types | G39: A segmented, jointed mechanism that grasps or moves objects, controlled by an operator or programmable logic. | H39: The manipulator moves objects with its jointed arm. | I39: يحرّك المُناوِل الأجسام بذراعه المفصلية. | J39: A manipulator can be controlled by an operator or a program. | K39: يمكن التحكم بالمُناوِل بواسطة مشغّل أو برنامج. | L39: Beginner | M39: 1 | N39: 1 – Robotics Fundamentals | أساسيات الروبوتات | O39: Normal | Q39: FutureLearn (Univ. of Reading) + Productivity Inc | R39: https://ugc.futurelearn.com/uploads/files/7a/0f/7a0fcf86-09f0-4ebf-a134-02b1290a950e/Glossary.pdf | https://www.productivity.com/wp-content/uploads/2015/04/PI_RoboticGlossaryTerms.pdf | S39: Definition paraphrased from the listed source(s); pronunciation, Arabic, examples and level are original additions.
A40: S1-MECH-007 | B40: 36 | C40: Mechanical | D40: ميكانيكي | E40: muh-KAN-ih-kul | F40: Mechanical | G40: Relating to machines and apparatus. | H40: The mechanical parts of the robot include gears and links. | I40: تشمل الأجزاء الميكانيكية للروبوت التروس والوصلات. | J40: A mechanical fault can cause noise and vibration. | K40: قد يسبب العطل الميكانيكي ضجيجاً واهتزازاً. | L40: Beginner | M40: 1 | N40: 1 – Robotics Fundamentals | أساسيات الروبوتات | O40: Normal | Q40: Productivity Inc | R40: https://www.productivity.com/wp-content/uploads/2015/04/PI_RoboticGlossaryTerms.pdf | S40: Definition paraphrased from the listed source(s); pronunciation, Arabic, examples and level are original additions.
A41: S1-FUND-005 | B41: 37 | C41: Mechatronics | D41: الميكاترونيكس | E41: mek-uh-TRON-iks | F41: Fundamentals | G41: The integrated design approach combining mechanical, electronic, control, and software engineering in one system. | H41: Mechatronics combines mechanics, electronics, and software. | I41: تجمع الميكاترونيكس بين الميكانيك والإلكترونيات والبرمجيات. | J41: He studies mechatronics at the engineering faculty. | K41: يدرس الميكاترونيكس في كلية الهندسة. | L41: Beginner | M41: 1 | N41: 1 – Robotics Fundamentals | أساسيات الروبوتات | O41: Normal | Q41: Engineers Universe + FutureLearn (Univ. of Reading) | R41: https://engineersuniverse.com/studios/mechatronics/mechatronics-terminology-glossary | https://ugc.futurelearn.com/uploads/files/7a/0f/7a0fcf86-09f0-4ebf-a134-02b1290a950e/Glossary.pdf | S41: Definition paraphrased from the listed source(s); pronunciation, Arabic, examples and level are original additions.
...

Sheet S1 Fundamentals
A1: Stage 1: Robotics Fundamentals — أساسيات الروبوتات
A2: What a robot is: parts, joints, robot types, basic geometry and terms. | ما هو الروبوت: أجزاؤه ومفاصله وأنواعه والمصطلحات والهندسة الأساسية.
A4: content_id | B4: # | C4: Term | D4: Arabic meaning | E4: Pronunciation | F4: Category | G4: Simple English definition | H4: Example 1 | I4: Arabic translation 1 | J4: Example 2 | K4: Arabic translation 2 | L4: Difficulty level | M4: Stage # | N4: Curriculum stage | O4: Interview priority | P4: Linked Q&A / troubleshooting | Q4: Source | R4: source_url | S4: Copyright/source note
A5: S1-KINE-001 | B5: 1 | C5: Acceleration | D5: التسارع | E5: ak-sel-er-AY-shun | F5: Kinematics | G5: A change in how fast something moves or in its direction of travel. | H5: The robot needs high acceleration to move quickly. | I5: يحتاج الروبوت إلى تسارع عالٍ ليتحرك بسرعة. | J5: Acceleration is the change of velocity over time. | K5: التسارع هو تغير السرعة عبر الزمن. | L5: Beginner | M5: 1 | N5: 1 – Robotics Fundamentals | أساسيات الروبوتات | O5: Normal | Q5: FutureLearn (Univ. of Reading) | R5: https://ugc.futurelearn.com/uploads/files/7a/0f/7a0fcf86-09f0-4ebf-a134-02b1290a950e/Glossary.pdf | S5: Definition paraphrased from the listed source(s); pronunciation, Arabic, examples and level are original additions.
A6: S1-PROG-001 | B6: 2 | C6: Algorithm | D6: خوارزمية | E6: AL-guh-rith-um | F6: Programming | G6: A set of steps for solving a problem. | H6: The algorithm tells the robot how to find the shortest path. | I6: تخبر الخوارزمية الروبوت كيف يجد أقصر مسار. | J6: We improved the algorithm to reduce the calculation time. | K6: حسّنا الخوارزمية لتقليل زمن الحساب. | L6: Beginner | M6: 1 | N6: 1 – Robotics Fundamentals | أساسيات الروبوتات | O6: Normal | Q6: FutureLearn (Univ. of Reading) + Productivity Inc | R6: https://ugc.futurelearn.com/uploads/files/7a/0f/7a0fcf86-09f0-4ebf-a134-02b1290a950e/Glossary.pdf | https://www.productivity.com/wp-content/uploads/2015/04/PI_RoboticGlossaryTerms.pdf | S6: Definition paraphrased from the listed source(s); pronunciation, Arabic, examples and level are original additions.
A7: S1-ROBT-001 | B7: 3 | C7: Android | D7: روبوت شبيه بالإنسان (أندرويد) | E7: AN-droyd | F7: Robot Types | G7: A robot that resembles a human to some degree. | H7: An android is a robot that looks like a human. | I7: الأندرويد روبوت يشبه الإنسان. | J7: The museum has an android that greets visitors. | K7: لدى المتحف روبوت شبيه بالإنسان يستقبل الزوار. | L7: Beginner | M7: 1 | N7: 1 – Robotics Fundamentals | أساسيات الروبوتات | O7: Normal | Q7: FutureLearn (Univ. of Reading) | R7: https://ugc.futurelearn.com/uploads/files/7a/0f/7a0fcf86-09f0-4ebf-a134-02b1290a950e/Glossary.pdf | S7: Definition paraphrased from the listed source(s); pronunciation, Arabic, examples and level are original additions.
A8: S1-MECH-001 | B8: 4 | C8: Arm | D8: الذراع | E8: ARM | F8: Mechanical | G8: The linked, powered segments of a manipulator that move the wrist and end-effector, excluding the end-effector itself. | H8: The robot arm can lift up to ten kilograms. | I8: يستطيع ذراع الروبوت رفع ما يصل إلى عشرة كيلوغرامات. | J8: The arm has six joints and a gripper at its end. | K8: للذراع ستة مفاصل وقابض في نهايتها. | L8: Beginner | M8: 1 | N8: 1 – Robotics Fundamentals | أساسيات الروبوتات | O8: Normal | Q8: Productivity Inc | R8: https://www.productivity.com/wp-content/uploads/2015/04/PI_RoboticGlossaryTerms.pdf | S8: Definition paraphrased from the listed source(s); pronunciation, Arabic, examples and level are original additions.
A9: S1-CMAI-001 | B9: 5 | C9: Artificial Intelligence | D9: الذكاء الاصطناعي | E9: ar-tih-FISH-ul in-TEL-ih-juns | F9: Computing & AI | G9: Intelligence shown by a machine. | H9: Artificial intelligence lets machines learn from data. | I9: يتيح الذكاء الاصطناعي للآلات التعلم من البيانات. | J9: Modern robots use artificial intelligence to recognize objects. | K9: تستخدم الروبوتات الحديثة الذكاء الاصطناعي للتعرف على الأجسام. | L9: Beginner | M9: 1 | N9: 1 – Robotics Fundamentals | أساسيات الروبوتات | O9: Normal | Q9: FutureLearn (Univ. of Reading) | R9: https://ugc.futurelearn.com/uploads/files/7a/0f/7a0fcf86-09f0-4ebf-a134-02b1290a950e/Glossary.pdf | S9: Definition paraphrased from the listed source(s); pronunciation, Arabic, examples and level are original additions.
A10: S1-ROBT-003 | B10: 6 | C10: Autonomous | D10: ذاتي التشغيل / مستقل | E10: aw-TON-uh-mus | F10: Robot Types | G10: Procedures that run without worker involvement and follow pre-programmed operations. | H10: An autonomous robot makes its own decisions without a human. | I10: يتخذ الروبوت الذاتي التشغيل قراراته بنفسه دون إنسان. | J10: Autonomous vehicles use sensors to avoid obstacles. | K10: تستخدم المركبات ذاتية القيادة الحساسات لتجنب العوائق. | L10: Beginner | M10: 1 | N10: 1 – Robotics Fundamentals | أساسيات الروبوتات | O10: Normal | Q10: FutureLearn (Univ. of Reading) + Productivity Inc | R10: https://ugc.futurelearn.com/uploads/files/7a/0f/7a0fcf86-09f0-4ebf-a134-02b1290a950e/Glossary.pdf | https://www.productivity.com/wp-content/uploads/2015/04/PI_RoboticGlossaryTerms.pdf | S10: Definition paraphrased from the listed source(s); pronunciation, Arabic, examples and level are original additions.
A11: S1-KINE-002 | B11: 7 | C11: Axis | D11: محور | E11: AK-sis | F11: Kinematics | G11: A direction or line of rotation along which a robot moves; most industrial robots have four or six. | H11: This robot has six axes of movement. | I11: لهذا الروبوت ستة محاور للحركة. | J11: Each axis is driven by its own servo motor. | K11: يُدار كل محور بمحرك مؤازر خاص به. | L11: Beginner | M11: 1 | N11: 1 – Robotics Fundamentals | أساسيات الروبوتات | O11: High | P11: S7-INTV-002 | Q11: Productivity Inc | R11: https://www.productivity.com/wp-content/uploads/2015/04/PI_RoboticGlossaryTerms.pdf | S11: Definition paraphrased from the listed source(s); pronunciation, Arabic, examples and level are original additions.
A12: S1-MECH-003 | B12: 8 | C12: Base | D12: القاعدة | E12: BAYSS | F12: Mechanical | G12: The stable platform to which a robotic arm is attached. | H12: The robot arm is bolted to a stable base. | I12: الذراع الآلية مثبّتة بمسامير على قاعدة ثابتة. | J12: The base must be level before installation. | K12: يجب أن تكون القاعدة مستوية قبل التركيب. | L12: Beginner | M12: 1 | N12: 1 – Robotics Fundamentals | أساسيات الروبوتات | O12: Normal | Q12: Productivity Inc | R12: https://www.productivity.com/wp-content/uploads/2015/04/PI_RoboticGlossaryTerms.pdf | S12: Definition paraphrased from the listed source(s); pronunciation, Arabic, examples and level are original additions.
A13: S1-SWDS-001 | B13: 9 | C13: CAD (Computer-Aided Design) | D13: التصميم بمساعدة الحاسوب | E13: KAD | F13: Software & Design | G13: Software for designing manufacturable parts, creating schematics, and simulating stresses on them. | H13: We drew the gripper in CAD before building it. | I13: رسمنا القابض في برنامج التصميم بمساعدة الحاسوب قبل تصنيعه. | J13: CAD software can simulate stress on a part. | K13: يستطيع برنامج التصميم بمساعدة الحاسوب محاكاة الإجهاد على القطعة. | L13: Beginner | M13: 1 | N13: 1 – Robotics Fundamentals | أساسيات الروبوتات | O13: Normal | Q13: Productivity Inc | R13: https://www.productivity.com/wp-content/uploads/2015/04/PI_RoboticGlossaryTerms.pdf | S13: Definition paraphrased from the listed source(s); pronunciation, Arabic, examples and level are original additions.
A14: S1-ROBT-006 | B14: 10 | C14: Cartesian Robot | D14: روبوت ديكارتي | E14: kar-TEE-zhun ROH-bot | F14: Robot Types | G14: A robot whose three linear joints run in the directions of a Cartesian coordinate system. | H14: A Cartesian robot has three linear axes. | I14: للروبوت الديكارتي ثلاثة محاور خطية. | J14: We used a Cartesian robot to stack boxes. | K14: استخدمنا روبوتاً ديكارتياً لتكديس الصناديق. | L14: Beginner | M14: 1 | N14: 1 – Robotics Fundamentals | أساسيات الروبوتات | O14: Normal | Q14: Productivity Inc | R14: https://www.productivity.com/wp-content/uploads/2015/04/PI_RoboticGlossaryTerms.pdf | S14: Definition paraphrased from the listed source(s); pronunciation, Arabic, examples and level are original additions.
A15: S1-MECH-004 | B15: 11 | C15: Chassis | D15: الهيكل | E15: SHAS-ee | F15: Mechanical | G15: The framework and internal parts of a machine, excluding its body or casing. | H15: The motors and batteries are mounted on the chassis. | I15: المحركات والبطاريات مركّبة على الهيكل. | J15: A strong chassis protects the electronics. | K15: الهيكل المتين يحمي الإلكترونيات. | L15: Beginner | M15: 1 | N15: 1 – Robotics Fundamentals | أساسيات الروبوتات | O15: Normal | Q15: Productivity Inc | R15: https://www.productivity.com/wp-content/uploads/2015/04/PI_RoboticGlossaryTerms.pdf | S15: Definition paraphrased from the listed source(s); pronunciation, Arabic, examples and level are original additions.
A16: S1-KINE-003 | B16: 12 | C16: Coordinates | D16: الإحداثيات | E16: koh-OR-dih-nits | F16: Kinematics | G16: A set of numbers that describes a position in two or three dimensions. | H16: The coordinates give the position of the point. | I16: تعطي الإحداثيات موضع النقطة. | J16: Enter the coordinates in millimeters. | K16: أدخل الإحداثيات بالملّيمترات. | L16: Beginner | M16: 1 | N16: 1 – Robotics Fundamentals | أساسيات الروبوتات | O16: Normal | Q16: FutureLearn (Univ. of Reading) | R16: https://ugc.futurelearn.com/uploads/files/7a/0f/7a0fcf86-09f0-4ebf-a134-02b1290a950e/Glossary.pdf | S16: Definition paraphrased from the listed source(s); pronunciation, Arabic, examples and level are original additions.
A17: S1-ROBT-009 | B17: 13 | C17: Cyborg | D17: سايبورغ (كائن سيبراني) | E17: SY-borg | F17: Robot Types | G17: An organism combining biological and mechanical or electronic parts. | H17: A cyborg combines a living body with machine parts. | I17: يجمع السايبورغ بين جسم حي وأجزاء آلية. | J17: Science fiction often shows cyborgs with robotic arms. | K17: يعرض الخيال العلمي غالباً سايبورغ بأذرع آلية. | L17: Beginner | M17: 1 | N17: 1 – Robotics Fundamentals | أساسيات الروبوتات | O17: Normal | Q17: FutureLearn (Univ. of Reading) | R17: https://ugc.futurelearn.com/uploads/files/7a/0f/7a0fcf86-09f0-4ebf-a134-02b1290a950e/Glossary.pdf | S17: Definition paraphrased from the listed source(s); pronunciation, Arabic, examples and level are original additions.
A18: S1-FUND-001 | B18: 14 | C18: Degrees | D18: الدرجات | E18: dih-GREEZ | F18: Fundamentals | G18: A unit for measuring angles, where a full turn is 360 degrees. | H18: A full circle has 360 degrees. | I18: للدائرة الكاملة 360 درجة. | J18: The joint rotates 90 degrees. | K18: يدور المفصل 90 درجة. | L18: Beginner | M18: 1 | N18: 1 – Robotics Fundamentals | أساسيات الروبوتات | O18: Normal | Q18: FutureLearn (Univ. of Reading) | R18: https://ugc.futurelearn.com/uploads/files/7a/0f/7a0fcf86-09f0-4ebf-a134-02b1290a950e/Glossary.pdf | S18: Definition paraphrased from the listed source(s); pronunciation, Arabic, examples and level are original additions.
A19: S1-KINE-004 | B19: 15 | C19: Degrees of Freedom (DOF) | D19: درجات الحرية | E19: dih-GREEZ uv FREE-dum | F19: Kinematics | G19: The number of independent parameters needed to define a system's position and orientation. | H19: This robot has six degrees of freedom. | I19: لهذا الروبوت ست درجات حرية. | J19: More degrees of freedom give more flexibility but harder control. | K19: مزيد من درجات الحرية يعطي مرونة أكبر لكن تحكماً أصعب. | L19: Beginner | M19: 1 | N19: 1 – Robotics Fundamentals | أساسيات الروبوتات | O19: High | P19: S7-INTV-002 | Q19: Engineers Universe + FutureLearn (Univ. of Reading) + Productivity Inc | R19: https://engineersuniverse.com/studios/mechatronics/mechatronics-terminology-glossary | https://ugc.futurelearn.com/uploads/files/7a/0f/7a0fcf86-09f0-4ebf-a134-02b1290a950e/Glossary.pdf | https://www.productivity.com/wp-content/uploads/2015/04/PI_RoboticGlossaryTerms.pdf | S19: Definition paraphrased from the listed source(s); pronunciation, Arabic, examples and level are original additions.
A20: S1-FUND-002 | B20: 16 | C20: Device | D20: جهاز | E20: dih-VYSE | F20: Fundamentals | G20: Hardware used to control parts of a system. | H20: Each device on the network has its own address. | I20: لكل جهاز على الشبكة عنوانه الخاص. | J20: The device controls part of the system. | K20: يتحكم الجهاز في جزء من النظام. | L20: Beginner | M20: 1 | N20: 1 – Robotics Fundamentals | أساسيات الروبوتات | O20: Normal | Q20: Productivity Inc | R20: https://www.productivity.com/wp-content/uploads/2015/04/PI_RoboticGlossaryTerms.pdf | S20: Definition paraphrased from the listed source(s); pronunciation, Arabic, examples and level are original additions.
A21: S1-ELEC-001 | B21: 17 | C21: Electronics | D21: الإلكترونيات | E21: ih-lek-TRON-iks | F21: Electronics | G21: The study of how electrons flow through and are controlled by components like batteries, resistors, and motors. | H21: Electronics is the study of circuits and components. | I21: الإلكترونيات هي دراسة الدوائر والمكونات. | J21: Robots depend on electronics to sense and control. | K21: تعتمد الروبوتات على الإلكترونيات للاستشعار والتحكم. | L21: Beginner | M21: 1 | N21: 1 – Robotics Fundamentals | أساسيات الروبوتات | O21: Normal | Q21: FutureLearn (Univ. of Reading) | R21: https://ugc.futurelearn.com/uploads/files/7a/0f/7a0fcf86-09f0-4ebf-a134-02b1290a950e/Glossary.pdf | S21: Definition paraphrased from the listed source(s); pronunciation, Arabic, examples and level are original additions.
A22: S1-TOOL-001 | B22: 18 | C22: End Effector | D22: المؤثر النهائي | E22: END ih-FEK-ter | F22: Tooling | G22: The tool at the end of a robot arm that interacts with the environment, such as a gripper or torch. | H22: The end effector of this robot is a vacuum gripper. | I22: المؤثر النهائي لهذا الروبوت قابض تفريغ. | J22: We changed the end effector to handle a larger part. | K22: غيّرنا المؤثر النهائي للتعامل مع قطعة أكبر. | L22: Beginner | M22: 1 | N22: 1 – Robotics Fundamentals | أساسيات الروبوتات | O22: Normal | Q22: Engineers Universe + FutureLearn (Univ. of Reading) + Productivity Inc | R22: https://engineersuniverse.com/studios/mechatronics/mechatronics-terminology-glossary | https://ugc.futurelearn.com/uploads/files/7a/0f/7a0fcf86-09f0-4ebf-a134-02b1290a950e/Glossary.pdf | https://www.productivity.com/wp-content/uploads/2015/04/PI_RoboticGlossaryTerms.pdf | S22: Definition paraphrased from the listed source(s); pronunciation, Arabic, examples and level are original additions.
A23: S1-FUND-003 | B23: 19 | C23: Energy Source | D23: مصدر الطاقة | E23: EN-er-jee SORS | F23: Fundamentals | G23: Where energy comes from, such as chemical, thermal, or mechanical processes. | H23: A battery is the energy source of a mobile robot. | I23: البطارية هي مصدر الطاقة للروبوت المتنقل. | J23: Choose an energy source that matches the actuators. | K23: اختر مصدر طاقة يناسب المشغّلات. | L23: Beginner | M23: 1 | N23: 1 – Robotics Fundamentals | أساسيات الروبوتات | O23: Normal | Q23: Productivity Inc | R23: https://www.productivity.com/wp-content/uploads/2015/04/PI_RoboticGlossaryTerms.pdf | S23: Definition paraphrased from the listed source(s); pronunciation, Arabic, examples and level are original additions.
A24: S1-FUND-004 | B24: 20 | C24: Flexibility | D24: المرونة | E24: flek-suh-BIL-ih-tee | F24: Fundamentals | G24: The range of diverse jobs a robot can perform. | H24: Flexibility lets one robot do many different jobs. | I24: تتيح المرونة لروبوت واحد القيام بمهام كثيرة مختلفة. | J24: The line needs flexibility because products change often. | K24: يحتاج الخط إلى المرونة لأن المنتجات تتغير كثيراً. | L24: Beginner | M24: 1 | N24: 1 – Robotics Fundamentals | أساسيات الروبوتات | O24: Normal | Q24: Productivity Inc | R24: https://www.productivity.com/wp-content/uploads/2015/04/PI_RoboticGlossaryTerms.pdf | S24: Definition paraphrased from the listed source(s); pronunciation, Arabic, examples and level are original additions.
A25: S1-DYNM-001 | B25: 21 | C25: Force | D25: القوة | E25: FORS | F25: Dynamics | G25: The strength behind an action or movement. | H25: The motor creates a force that moves the arm. | I25: يخلق المحرك قوة تحرك الذراع. | J25: Force is measured in newtons. | K25: تُقاس القوة بالنيوتن. | L25: Beginner | M25: 1 | N25: 1 – Robotics Fundamentals | أساسيات الروبوتات | O25: Normal | Q25: FutureLearn (Univ. of Reading) | R25: https://ugc.futurelearn.com/uploads/files/7a/0f/7a0fcf86-09f0-4ebf-a134-02b1290a950e/Glossary.pdf | S25: Definition paraphrased from the listed source(s); pronunciation, Arabic, examples and level are original additions.
A26: S1-TOOL-002 | B26: 22 | C26: Gripper | D26: القابض | E26: GRIP-er | F26: Tooling | G26: An end-effector that seizes and holds objects through pressure, magnetism, or vacuum. | H26: The gripper holds the bottle without dropping it. | I26: يمسك القابض الزجاجة دون إسقاطها. | J26: A magnetic gripper can pick up steel parts. | K26: يستطيع القابض المغناطيسي التقاط القطع الفولاذية. | L26: Beginner | M26: 1 | N26: 1 – Robotics Fundamentals | أساسيات الروبوتات | O26: High | P26: S7-TRBL-006 | Q26: FutureLearn (Univ. of Reading) + Productivity Inc | R26: https://ugc.futurelearn.com/uploads/files/7a/0f/7a0fcf86-09f0-4ebf-a134-02b1290a950e/Glossary.pdf | https://www.productivity.com/wp-content/uploads/2015/04/PI_RoboticGlossaryTerms.pdf | S26: Definition paraphrased from the listed source(s); pronunciation, Arabic, examples and level are original additions.
A27: S1-TOOL-003 | B27: 23 | C27: Hand | D27: اليد | E27: HAND | F27: Tooling | G27: A clamp or gripper used as an end-effector to grasp objects. | H27: The robot hand can hold small objects. | I27: تستطيع يد الروبوت حمل الأشياء الصغيرة. | J27: A two-finger hand is enough for this task. | K27: يد بإصبعين تكفي لهذه المهمة. | L27: Beginner | M27: 1 | N27: 1 – Robotics Fundamentals | أساسيات الروبوتات | O27: Normal | Q27: Productivity Inc | R27: https://www.productivity.com/wp-content/uploads/2015/04/PI_RoboticGlossaryTerms.pdf | S27: Definition paraphrased from the listed source(s); pronunciation, Arabic, examples and level are original additions.
A28: S1-EMBD-001 | B28: 24 | C28: Hardware | D28: العتاد (الأجهزة) | E28: HARD-wair | F28: Embedded Systems | G28: The physical parts of a computer. | H28: The hardware includes the motors, sensors, and controller. | I28: يشمل العتاد المحركات والحساسات والمتحكم. | J28: We replaced the faulty hardware, not the software. | K28: استبدلنا العتاد المعطوب وليس البرمجيات. | L28: Beginner | M28: 1 | N28: 1 – Robotics Fundamentals | أساسيات الروبوتات | O28: Normal | Q28: FutureLearn (Univ. of Reading) | R28: https://ugc.futurelearn.com/uploads/files/7a/0f/7a0fcf86-09f0-4ebf-a134-02b1290a950e/Glossary.pdf | S28: Definition paraphrased from the listed source(s); pronunciation, Arabic, examples and level are original additions.
A29: S1-ROBT-014 | B29: 25 | C29: Industrial Robot | D29: روبوت صناعي | E29: in-DUS-tree-ul ROH-bot | F29: Robot Types | G29: A reprogrammable multifunction manipulator that moves materials, parts, tools, or devices through varied programmed motions. | H29: An industrial robot is a reprogrammable multi-purpose manipulator. | I29: الروبوت الصناعي ذراع متعددة الأغراض قابلة لإعادة البرمجة. | J29: The industrial robot paints car bodies all day. | K29: يطلي الروبوت الصناعي هياكل السيارات طوال اليوم. | L29: Beginner | M29: 1 | N29: 1 – Robotics Fundamentals | أساسيات الروبوتات | O29: Normal | Q29: FutureLearn (Univ. of Reading) + Productivity Inc | R29: https://ugc.futurelearn.com/uploads/files/7a/0f/7a0fcf86-09f0-4ebf-a134-02b1290a950e/Glossary.pdf | https://www.productivity.com/wp-content/uploads/2015/04/PI_RoboticGlossaryTerms.pdf | S29: Definition paraphrased from the listed source(s); pronunciation, Arabic, examples and level are original additions.
A30: S1-ROBT-015 | B30: 26 | C30: Insect robot | D30: روبوت حشري | E30: IN-sekt ROH-bot | F30: Robot Types | G30: A small mobile robot. | H30: An insect robot is small and walks on six legs. | I30: الروبوت الحشري صغير ويمشي على ست أرجل. | J30: The insect robot can climb over small obstacles. | K30: يستطيع الروبوت الحشري تسلق عوائق صغيرة. | L30: Beginner | M30: 1 | N30: 1 – Robotics Fundamentals | أساسيات الروبوتات | O30: Normal | Q30: FutureLearn (Univ. of Reading) | R30: https://ugc.futurelearn.com/uploads/files/7a/0f/7a0fcf86-09f0-4ebf-a134-02b1290a950e/Glossary.pdf | S30: Definition paraphrased from the listed source(s); pronunciation, Arabic, examples and level are original additions.
A31: S1-CMAI-004 | B31: 27 | C31: Intelligence | D31: الذكاء | E31: in-TEL-ih-juns | F31: Computing & AI | G31: The capacity to gain and use skills and knowledge. | H31: Intelligence is the ability to learn and use knowledge. | I31: الذكاء هو القدرة على التعلم واستخدام المعرفة. | J31: Robots with some intelligence can adapt to change. | K31: الروبوتات ذات الذكاء المحدود تستطيع التكيف مع التغيير. | L31: Beginner | M31: 1 | N31: 1 – Robotics Fundamentals | أساسيات الروبوتات | O31: Normal | Q31: FutureLearn (Univ. of Reading) | R31: https://ugc.futurelearn.com/uploads/files/7a/0f/7a0fcf86-09f0-4ebf-a134-02b1290a950e/Glossary.pdf | S31: Definition paraphrased from the listed source(s); pronunciation, Arabic, examples and level are original additions.
A32: S1-ROBT-016 | B32: 28 | C32: Intelligent Robot | D32: روبوت ذكي | E32: in-TEL-ih-junt ROH-bot | F32: Robot Types | G32: A robot that can make performance choices based on sensory input with little human help. | H32: An intelligent robot can choose actions based on its sensors. | I32: يستطيع الروبوت الذكي اختيار الأفعال بناءً على حساساته. | J32: Intelligent robots need little help from humans. | K32: لا تحتاج الروبوتات الذكية إلا إلى مساعدة قليلة من البشر. | L32: Beginner | M32: 1 | N32: 1 – Robotics Fundamentals | أساسيات الروبوتات | O32: Normal | Q32: FutureLearn (Univ. of Reading) + Productivity Inc | R32: https://ugc.futurelearn.com/uploads/files/7a/0f/7a0fcf86-09f0-4ebf-a134-02b1290a950e/Glossary.pdf | https://www.productivity.com/wp-content/uploads/2015/04/PI_RoboticGlossaryTerms.pdf | S32: Definition paraphrased from the listed source(s); pronunciation, Arabic, examples and level are original additions.
A33: S1-MECH-005 | B33: 29 | C33: Joint | D33: مفصل | E33: JOYNT | F33: Mechanical | G33: A rotational or translational degree of freedom between links or between a link and the end-effector. | H33: Each joint of the robot has its own motor. | I33: لكل مفصل في الروبوت محركه الخاص. | J33: The elbow joint rotates up to 150 degrees. | K33: يدور مفصل المرفق حتى 150 درجة. | L33: Beginner | M33: 1 | N33: 1 – Robotics Fundamentals | أساسيات الروبوتات | O33: High | P33: S7-INTV-002 | Q33: FutureLearn (Univ. of Reading) + Productivity Inc | R33: https://ugc.futurelearn.com/uploads/files/7a/0f/7a0fcf86-09f0-4ebf-a134-02b1290a950e/Glossary.pdf | https://www.productivity.com/wp-content/uploads/2015/04/PI_RoboticGlossaryTerms.pdf | S33: Definition paraphrased from the listed source(s); pronunciation, Arabic, examples and level are original additions.
A34: S1-ROBT-017 | B34: 30 | C34: Jointed Arm Robot | D34: روبوت ذو ذراع مفصلية | E34: JOYN-tid ARM ROH-bot | F34: Robot Types | G34: A robot arm with two junctions that allow motion similar to a human shoulder and elbow. | H34: A jointed arm robot moves like a human shoulder and elbow. | I34: يتحرك الروبوت ذو الذراع المفصلية مثل كتف الإنسان ومرفقه. | J34: Most welding robots are jointed arm robots. | K34: معظم روبوتات اللحام ذات أذرع مفصلية. | L34: Beginner | M34: 1 | N34: 1 – Robotics Fundamentals | أساسيات الروبوتات | O34: Normal | Q34: Productivity Inc | R34: https://www.productivity.com/wp-content/uploads/2015/04/PI_RoboticGlossaryTerms.pdf | S34: Definition paraphrased from the listed source(s); pronunciation, Arabic, examples and level are original additions.
A35: S1-ETHC-001 | B35: 31 | C35: Law of Robotics | D35: قوانين الروبوتات | E35: LAW uv roh-BOT-iks | F35: Robotics Ethics | G35: Rules created by Isaac Asimov in his robot stories to govern robot behavior. | H35: Asimov wrote the three laws of robotics. | I35: كتب أسيموف قوانين الروبوتات الثلاثة. | J35: The first law says a robot must not harm a human. | K35: ينص القانون الأول على أن الروبوت يجب ألا يؤذي إنساناً. | L35: Beginner | M35: 1 | N35: 1 – Robotics Fundamentals | أساسيات الروبوتات | O35: Normal | Q35: FutureLearn (Univ. of Reading) | R35: https://ugc.futurelearn.com/uploads/files/7a/0f/7a0fcf86-09f0-4ebf-a134-02b1290a950e/Glossary.pdf | S35: Definition paraphrased from the listed source(s); pronunciation, Arabic, examples and level are original additions.
